Workbook

Sheet Sheet1
A2: - Selected the variables/data for the 35 countries of group 2019-2022 and used the same group of countries to select the variables/data for 2012-2022
A3: - Countries: Brazil, Canada, Chile, Colombia, Croatia, Cyprus, Egypt, Germany, Greece, Guatemala, India, Iran, Israel, Japan, Latvia, Luxembourg, Morocco, Netherlands, Norway, Oman, Panama, Poland, Qatar, Saudi Arabia, Slovakia, Slovenia, South Africa, South Korea, Spain, Sweden, Switzerland, Taiwan, United Arab Emirates, United Kingdom, United States
A4: - Removed Nbstat from 2012-2022 as it was the only variable with too many missing data
A5: - Removed 9 countries from the 2012-2022 group with more than 1 variable with missing data for more than 1 consecutive year
A6: - Removed 6 countries from the 2019-2022 group with Nbstat missing as it was the only variable with missing data for more than 1 consecutive year
A7: - Intepolated data (w/average) for 2012-2022 (all variables): Canada (2012), Guatemala (2012), India (2012), Israel (2012), Latvia (2014, 2018), Luxembourg (2012), South Africa (2018, 2020), South Korea (2014), Taiwan (2021)
A8: - Intepolated data (w/average) for 2019-2022 (all variables): Japan (2020), South Africa (2020), Taiwan (2021), Canada (Nbstat, 2021)
A9: - Baseline sample (S2012-2022 & S2019-2022) removes years with interpolated data - Unbalanced panel
A10: - Y(TEA 18-34) = (Teaap1 + Teaap2) / ((Teaap1 / Teaac1) + (Teaap2 / Teaac2))
A11: - Variables standardised with (xi,t-avg(xi))/std(xi)
A13: - Data
A14: Sample: S2012-2022 & S2019-2022
... A26: Script and a short codebook mapping the GEM variable names to X1–X8 in Section 7.2.1

Sheet S2012-2022
A1: Country | B1: Year | C1: Region | D1: Income Group | E1: TEA_18_34 | F1: Teaap1 | G1: Teaap2 | H1: Teaac1 | I1: Teaac2 | J1: Suskil | K1: Futsup | L1: Knoent | M1: Frfail | N1: Opport | O1: RQ
A2: Brazil | B2: 2012 | C2: Latin America & Caribbean | D2: Upper-middle income | E2: =('2012-2022'!E2-'2012-2022'!R$2)/'2012-2022'!R$3 -> 0.46131176 | F2: =('2012-2022'!F2-'2012-2022'!S$2)/'2012-2022'!S$3 -> 0.61320248 | G2: =('2012-2022'!G2-'2012-2022'!T$2)/'2012-2022'!T$3 -> 0.51305812 | H2: =('2012-2022'!H2-'2012-2022'!U$2)/'2012-2022'!U$3 -> 0.38704089 | I2: =('2012-2022'!I2-'2012-2022'!V$2)/'2012-2022'!V$3 -> 0.50009164 | J2: =('2012-2022'!J2-'2012-2022'!W$2)/'2012-2022'!W$3 -> 0.22079 | K2: =('2012-2022'!K2-'2012-2022'!X$2)/'2012-2022'!X$3 -> 1.1419892 | L2: =('2012-2022'!L2-'2012-2022'!Y$2)/'2012-2022'!Y$3 -> -0.64550296 | ... N2: =('2012-2022'!N2-'2012-2022'!AA$2)/'2012-2022'!AA$3 -> 0.47258317 | O2: =('2012-2022'!P2-'2012-2022'!AC$2)/'2012-2022'!AC$3 -> -0.80178649
A3: Brazil | B3: 2013 | C3: Latin America & Caribbean | D3: Upper-middle income | E3: =('2012-2022'!E3-'2012-2022'!R$2)/'2012-2022'!R$3 -> 0.80520701 | F3: =('2012-2022'!F3-'2012-2022'!S$2)/'2012-2022'!S$3 -> 0.42991577 | G3: =('2012-2022'!G3-'2012-2022'!T$2)/'2012-2022'!T$3 -> 0.40022211 | H3: =('2012-2022'!H3-'2012-2022'!U$2)/'2012-2022'!U$3 -> 0.66424304 | I3: =('2012-2022'!I3-'2012-2022'!V$2)/'2012-2022'!V$3 -> 0.8546701 | J3: =('2012-2022'!J3-'2012-2022'!W$2)/'2012-2022'!W$3 -> 0.10583261 | K3: =('2012-2022'!K3-'2012-2022'!X$2)/'2012-2022'!X$3 -> 0.54210743 | L3: =('2012-2022'!L3-'2012-2022'!Y$2)/'2012-2022'!Y$3 -> -0.30051546 | ... N3: =('2012-2022'!N3-'2012-2022'!AA$2)/'2012-2022'!AA$3 -> 0.38091909 | O3: =('2012-2022'!P3-'2012-2022'!AC$2)/'2012-2022'!AC$3 -> -0.87645841
A4: Brazil | B4: 2014 | C4: Latin America & Caribbean | D4: Upper-middle income | E4: =('2012-2022'!E4-'2012-2022'!R$2)/'2012-2022'!R$3 -> 0.81947257 | F4: =('2012-2022'!F4-'2012-2022'!S$2)/'2012-2022'!S$3 -> 0.65024617 | G4: =('2012-2022'!G4-'2012-2022'!T$2)/'2012-2022'!T$3 -> 0.57557358 | H4: =('2012-2022'!H4-'2012-2022'!U$2)/'2012-2022'!U$3 -> 0.66498584 | I4: =('2012-2022'!I4-'2012-2022'!V$2)/'2012-2022'!V$3 -> 0.89452695 | J4: =('2012-2022'!J4-'2012-2022'!W$2)/'2012-2022'!W$3 -> -0.12512146 | K4: =('2012-2022'!K4-'2012-2022'!X$2)/'2012-2022'!X$3 -> -0.0077939203 | L4: =('2012-2022'!L4-'2012-2022'!Y$2)/'2012-2022'!Y$3 -> -0.32076304 | ... N4: =('2012-2022'!N4-'2012-2022'!AA$2)/'2012-2022'!AA$3 -> 0.66759893 | O4: =('2012-2022'!P4-'2012-2022'!AC$2)/'2012-2022'!AC$3 -> -1.0858036
A5: Brazil | B5: 2015 | C5: Latin America & Caribbean | D5: Upper-middle income | E5: =('2012-2022'!E5-'2012-2022'!R$2)/'2012-2022'!R$3 -> 1.4124962 | F5: =('2012-2022'!F5-'2012-2022'!S$2)/'2012-2022'!S$3 -> 0.78124704 | G5: =('2012-2022'!G5-'2012-2022'!T$2)/'2012-2022'!T$3 -> 0.35944596 | H5: =('2012-2022'!H5-'2012-2022'!U$2)/'2012-2022'!U$3 -> 1.3070458 | I5: =('2012-2022'!I5-'2012-2022'!V$2)/'2012-2022'!V$3 -> 1.414457 | J5: =('2012-2022'!J5-'2012-2022'!W$2)/'2012-2022'!W$3 -> 0.59639616 | K5: =('2012-2022'!K5-'2012-2022'!X$2)/'2012-2022'!X$3 -> 0.095645263 | L5: =('2012-2022'!L5-'2012-2022'!Y$2)/'2012-2022'!Y$3 -> 0.79271187 | ... N5: =('2012-2022'!N5-'2012-2022'!AA$2)/'2012-2022'!AA$3 -> -0.15058706 | O5: =('2012-2022'!P5-'2012-2022'!AC$2)/'2012-2022'!AC$3 -> -1.1610231
A6: Brazil | B6: 2016 | C6: Latin America & Caribbean | D6: Upper-middle income | E6: =('2012-2022'!E6-'2012-2022'!R$2)/'2012-2022'!R$3 -> 1.1050953 | F6: =('2012-2022'!F6-'2012-2022'!S$2)/'2012-2022'!S$3 -> 0.85488076 | G6: =('2012-2022'!G6-'2012-2022'!T$2)/'2012-2022'!T$3 -> -0.012055777 | H6: =('2012-2022'!H6-'2012-2022'!U$2)/'2012-2022'!U$3 -> 1.2079504 | I6: =('2012-2022'!I6-'2012-2022'!V$2)/'2012-2022'!V$3 -> 0.98274853 | J6: =('2012-2022'!J6-'2012-2022'!W$2)/'2012-2022'!W$3 -> 0.18858427 | K6: =('2012-2022'!K6-'2012-2022'!X$2)/'2012-2022'!X$3 -> 0.43948567 | L6: =('2012-2022'!L6-'2012-2022'!Y$2)/'2012-2022'!Y$3 -> -0.034906039 | ... N6: =('2012-2022'!N6-'2012-2022'!AA$2)/'2012-2022'!AA$3 -> -0.28407509 | O6: =('2012-2022'!P6-'2012-2022'!AC$2)/'2012-2022'!AC$3 -> -1.160896
A7: Brazil | B7: 2017 | C7: Latin America & Caribbean | D7: Upper-middle income | E7: =('2012-2022'!E7-'2012-2022'!R$2)/'2012-2022'!R$3 -> 1.7235449 | F7: =('2012-2022'!F7-'2012-2022'!S$2)/'2012-2022'!S$3 -> 0.7297846 | G7: =('2012-2022'!G7-'2012-2022'!T$2)/'2012-2022'!T$3 -> 1.1797892 | H7: =('2012-2022'!H7-'2012-2022'!U$2)/'2012-2022'!U$3 -> 1.233148 | I7: =('2012-2022'!I7-'2012-2022'!V$2)/'2012-2022'!V$3 -> 1.9761987 | J7: =('2012-2022'!J7-'2012-2022'!W$2)/'2012-2022'!W$3 -> 0.39038107 | K7: =('2012-2022'!K7-'2012-2022'!X$2)/'2012-2022'!X$3 -> -0.27066779 | L7: =('2012-2022'!L7-'2012-2022'!Y$2)/'2012-2022'!Y$3 -> 0.077674937 | ... N7: =('2012-2022'!N7-'2012-2022'!AA$2)/'2012-2022'!AA$3 -> 0.10053571 | O7: =('2012-2022'!P7-'2012-2022'!AC$2)/'2012-2022'!AC$3 -> -1.1736093
A8: Brazil | B8: 2018 | C8: Latin America & Caribbean | D8: Upper-middle income | E8: =('2012-2022'!E8-'2012-2022'!R$2)/'2012-2022'!R$3 -> 0.95421375 | F8: =('2012-2022'!F8-'2012-2022'!S$2)/'2012-2022'!S$3 -> 1.2689781 | G8: =('2012-2022'!G8-'2012-2022'!T$2)/'2012-2022'!T$3 -> -0.31297931 | H8: =('2012-2022'!H8-'2012-2022'!U$2)/'2012-2022'!U$3 -> 1.3626428 | I8: =('2012-2022'!I8-'2012-2022'!V$2)/'2012-2022'!V$3 -> 0.62846872 | J8: =('2012-2022'!J8-'2012-2022'!W$2)/'2012-2022'!W$3 -> 0.24959855 | K8: =('2012-2022'!K8-'2012-2022'!X$2)/'2012-2022'!X$3 -> 0.3000493 | L8: =('2012-2022'!L8-'2012-2022'!Y$2)/'2012-2022'!Y$3 -> -0.58465767 | ... N8: =('2012-2022'!N8-'2012-2022'!AA$2)/'2012-2022'!AA$3 -> -0.83102874 | O8: =('2012-2022'!P8-'2012-2022'!AC$2)/'2012-2022'!AC$3 -> -1.3470426
A9: Brazil | B9: 2019 | C9: Latin America & Caribbean | D9: Upper-middle income | E9: =('2012-2022'!E9-'2012-2022'!R$2)/'2012-2022'!R$3 -> 1.6130318 | F9: =('2012-2022'!F9-'2012-2022'!S$2)/'2012-2022'!S$3 -> 0.7937986 | G9: =('2012-2022'!G9-'2012-2022'!T$2)/'2012-2022'!T$3 -> -0.39864155 | H9: =('2012-2022'!H9-'2012-2022'!U$2)/'2012-2022'!U$3 -> 1.789714 | I9: =('2012-2022'!I9-'2012-2022'!V$2)/'2012-2022'!V$3 -> 1.4075997 | J9: =('2012-2022'!J9-'2012-2022'!W$2)/'2012-2022'!W$3 -> 0.91969675 | K9: =('2012-2022'!K9-'2012-2022'!X$2)/'2012-2022'!X$3 -> 0.9091966 | L9: =('2012-2022'!L9-'2012-2022'!Y$2)/'2012-2022'!Y$3 -> 0.79056445 | ... N9: =('2012-2022'!N9-'2012-2022'!AA$2)/'2012-2022'!AA$3 -> 0.09750111 | O9: =('2012-2022'!P9-'2012-2022'!AC$2)/'2012-2022'!AC$3 -> -1.1649089
A10: Brazil | B10: 2020 | C10: Latin America & Caribbean | D10: Upper-middle income | E10: =('2012-2022'!E10-'2012-2022'!R$2)/'2012-2022'!R$3 -> 1.6891948 | F10: =('2012-2022'!F10-'2012-2022'!S$2)/'2012-2022'!S$3 -> 0.54710387 | G10: =('2012-2022'!G10-'2012-2022'!T$2)/'2012-2022'!T$3 -> -0.1544359 | H10: =('2012-2022'!H10-'2012-2022'!U$2)/'2012-2022'!U$3 -> 1.5883446 | I10: =('2012-2022'!I10-'2012-2022'!V$2)/'2012-2022'!V$3 -> 1.6740679 | J10: =('2012-2022'!J10-'2012-2022'!W$2)/'2012-2022'!W$3 -> 1.4272962 | K10: =('2012-2022'!K10-'2012-2022'!X$2)/'2012-2022'!X$3 -> 2.1548994 | L10: =('2012-2022'!L10-'2012-2022'!Y$2)/'2012-2022'!Y$3 -> 2.5914596 | ... N10: =('2012-2022'!N10-'2012-2022'!AA$2)/'2012-2022'!AA$3 -> 0.77778784 | O10: =('2012-2022'!P10-'2012-2022'!AC$2)/'2012-2022'!AC$3 -> -1.2308677
A11: Brazil | B11: 2021 | C11: Latin America & Caribbean | D11: Upper-middle income | E11: =('2012-2022'!E11-'2012-2022'!R$2)/'2012-2022'!R$3 -> 1.2758856 | F11: =('2012-2022'!F11-'2012-2022'!S$2)/'2012-2022'!S$3 -> -0.30446902 | G11: =('2012-2022'!G11-'2012-2022'!T$2)/'2012-2022'!T$3 -> 0.35898325 | H11: =('2012-2022'!H11-'2012-2022'!U$2)/'2012-2022'!U$3 -> 0.59120502 | I11: =('2012-2022'!I11-'2012-2022'!V$2)/'2012-2022'!V$3 -> 1.6394813 | J11: =('2012-2022'!J11-'2012-2022'!W$2)/'2012-2022'!W$3 -> 1.3305621 | K11: =('2012-2022'!K11-'2012-2022'!X$2)/'2012-2022'!X$3 -> 2.1124217 | L11: =('2012-2022'!L11-'2012-2022'!Y$2)/'2012-2022'!Y$3 -> 2.3041006 | ... N11: =('2012-2022'!N11-'2012-2022'!AA$2)/'2012-2022'!AA$3 -> 0.6218334 | O11: =('2012-2022'!P11-'2012-2022'!AC$2)/'2012-2022'!AC$3 -> -1.2298449
A12: Brazil | B12: 2022 | C12: Latin America & Caribbean | D12: Upper-middle income | E12: =('2012-2022'!E12-'2012-2022'!R$2)/'2012-2022'!R$3 -> 1.2560583 | F12: =('2012-2022'!F12-'2012-2022'!S$2)/'2012-2022'!S$3 -> 0.59344862 | G12: =('2012-2022'!G12-'2012-2022'!T$2)/'2012-2022'!T$3 -> -0.21864272 | H12: =('2012-2022'!H12-'2012-2022'!U$2)/'2012-2022'!U$3 -> 1.4409162 | I12: =('2012-2022'!I12-'2012-2022'!V$2)/'2012-2022'!V$3 -> 1.0583546 | J12: =('2012-2022'!J12-'2012-2022'!W$2)/'2012-2022'!W$3 -> 1.5419528 | K12: =('2012-2022'!K12-'2012-2022'!X$2)/'2012-2022'!X$3 -> 2.2446228 | L12: =('2012-2022'!L12-'2012-2022'!Y$2)/'2012-2022'!Y$3 -> 2.7134309 | ... N12: =('2012-2022'!N12-'2012-2022'!AA$2)/'2012-2022'!AA$3 -> 1.4338623 | O12: =('2012-2022'!P12-'2012-2022'!AC$2)/'2012-2022'!AC$3 -> -1.2900143
A13: Canada | B13: 2013 | C13: North America | D13: High income | E13: =('2012-2022'!E14-'2012-2022'!R$2)/'2012-2022'!R$3 -> 0.18655615 | F13: =('2012-2022'!F14-'2012-2022'!S$2)/'2012-2022'!S$3 -> -0.56318974 | G13: =('2012-2022'!G14-'2012-2022'!T$2)/'2012-2022'!T$3 -> 0.11048349 | H13: =('2012-2022'!H14-'2012-2022'!U$2)/'2012-2022'!U$3 -> -0.25141867 | I13: =('2012-2022'!I14-'2012-2022'!V$2)/'2012-2022'!V$3 -> 0.47470183 | J13: =('2012-2022'!J14-'2012-2022'!W$2)/'2012-2022'!W$3 -> -0.25577676 | K13: =('2012-2022'!K14-'2012-2022'!X$2)/'2012-2022'!X$3 -> -0.39875586 | L13: =('2012-2022'!L14-'2012-2022'!Y$2)/'2012-2022'!Y$3 -> -1.0973776 | ... N13: =('2012-2022'!N14-'2012-2022'!AA$2)/'2012-2022'!AA$3 -> 0.78031067 | O13: =('2012-2022'!P14-'2012-2022'!AC$2)/'2012-2022'!AC$3 -> 1.1642638
A14: Canada | B14: 2014 | C14: North America | D14: High income | E14: =('2012-2022'!E15-'2012-2022'!R$2)/'2012-2022'!R$3 -> 0.066263931 | F14: =('2012-2022'!F15-'2012-2022'!S$2)/'2012-2022'!S$3 -> -0.23038586 | G14: =('2012-2022'!G15-'2012-2022'!T$2)/'2012-2022'!T$3 -> -0.93616216 | H14: =('2012-2022'!H15-'2012-2022'!U$2)/'2012-2022'!U$3 -> 0.083092709 | I14: =('2012-2022'!I15-'2012-2022'!V$2)/'2012-2022'!V$3 -> 0.064878601 | J14: =('2012-2022'!J15-'2012-2022'!W$2)/'2012-2022'!W$3 -> -0.2103933 | K14: =('2012-2022'!K15-'2012-2022'!X$2)/'2012-2022'!X$3 -> -0.42025796 | L14: =('2012-2022'!L15-'2012-2022'!Y$2)/'2012-2022'!Y$3 -> -0.86417624 | ... N14: =('2012-2022'!N15-'2012-2022'!AA$2)/'2012-2022'!AA$3 -> 0.66640035 | O14: =('2012-2022'!P15-'2012-2022'!AC$2)/'2012-2022'!AC$3 -> 1.0752585
A15: Canada | B15: 2015 | C15: North America | D15: High income | E15: =('2012-2022'!E16-'2012-2022'!R$2)/'2012-2022'!R$3 -> 0.48797552 | F15: =('2012-2022'!F16-'2012-2022'!S$2)/'2012-2022'!S$3 -> 0.52111727 | G15: =('2012-2022'!G16-'2012-2022'!T$2)/'2012-2022'!T$3 -> -1.1494322 | H15: =('2012-2022'!H16-'2012-2022'!U$2)/'2012-2022'!U$3 -> 0.94186571 | I15: =('2012-2022'!I16-'2012-2022'!V$2)/'2012-2022'!V$3 -> 0.16490578 | J15: =('2012-2022'!J16-'2012-2022'!W$2)/'2012-2022'!W$3 -> -0.078476913 | K15: =('2012-2022'!K16-'2012-2022'!X$2)/'2012-2022'!X$3 -> -0.37177172 | L15: =('2012-2022'!L16-'2012-2022'!Y$2)/'2012-2022'!Y$3 -> -0.80721475 | ... N15: =('2012-2022'!N16-'2012-2022'!AA$2)/'2012-2022'!AA$3 -> 0.52127033 | O15: =('2012-2022'!P16-'2012-2022'!AC$2)/'2012-2022'!AC$3 -> 1.0456507
A16: Canada | B16: 2016 | C16: North America | D16: High income | E16: =('2012-2022'!E17-'2012-2022'!R$2)/'2012-2022'!R$3 -> 0.73732297 | F16: =('2012-2022'!F17-'2012-2022'!S$2)/'2012-2022'!S$3 -> -0.33367228 | G16: =('2012-2022'!G17-'2012-2022'!T$2)/'2012-2022'!T$3 -> -0.60342744 | H16: =('2012-2022'!H17-'2012-2022'!U$2)/'2012-2022'!U$3 -> 0.44345272 | I16: =('2012-2022'!I17-'2012-2022'!V$2)/'2012-2022'!V$3 -> 0.90440308 | J16: =('2012-2022'!J17-'2012-2022'!W$2)/'2012-2022'!W$3 -> 0.2323079 | K16: =('2012-2022'!K17-'2012-2022'!X$2)/'2012-2022'!X$3 -> -0.078952323 | L16: =('2012-2022'!L17-'2012-2022'!Y$2)/'2012-2022'!Y$3 -> -0.43148106 | ... N16: =('2012-2022'!N17-'2012-2022'!AA$2)/'2012-2022'!AA$3 -> 0.88049546 | O16: =('2012-2022'!P17-'2012-2022'!AC$2)/'2012-2022'!AC$3 -> 1.1859958
A17: Canada | B17: 2017 | C17: North America | D17: High income | E17: =('2012-2022'!E18-'2012-2022'!R$2)/'2012-2022'!R$3 -> 1.4769076 | F17: =('2012-2022'!F18-'2012-2022'!S$2)/'2012-2022'!S$3 -> -0.23434755 | G17: =('2012-2022'!G18-'2012-2022'!T$2)/'2012-2022'!T$3 -> 0.1473339 | H17: =('2012-2022'!H18-'2012-2022'!U$2)/'2012-2022'!U$3 -> 0.80281523 | I17: =('2012-2022'!I18-'2012-2022'!V$2)/'2012-2022'!V$3 -> 1.8467395 | J17: =('2012-2022'!J18-'2012-2022'!W$2)/'2012-2022'!W$3 -> 0.36366574 | K17: =('2012-2022'!K18-'2012-2022'!X$2)/'2012-2022'!X$3 -> 0.061334638 | L17: =('2012-2022'!L18-'2012-2022'!Y$2)/'2012-2022'!Y$3 -> -0.20045334 | ... N17: =('2012-2022'!N18-'2012-2022'!AA$2)/'2012-2022'!AA$3 -> 0.95898013 | O17: =('2012-2022'!P18-'2012-2022'!AC$2)/'2012-2022'!AC$3 -> 1.2783297
A18: Canada | B18: 2018 | C18: North America | D18: High income | E18: =('2012-2022'!E19-'2012-2022'!R$2)/'2012-2022'!R$3 -> 1.7798584 | F18: =('2012-2022'!F19-'2012-2022'!S$2)/'2012-2022'!S$3 -> 0.92911064 | G18: =('2012-2022'!G19-'2012-2022'!T$2)/'2012-2022'!T$3 -> -0.21127996 | H18: =('2012-2022'!H19-'2012-2022'!U$2)/'2012-2022'!U$3 -> 2.2053519 | I18: =('2012-2022'!I19-'2012-2022'!V$2)/'2012-2022'!V$3 -> 1.3966981 | J18: =('2012-2022'!J19-'2012-2022'!W$2)/'2012-2022'!W$3 -> 0.38739775 | K18: =('2012-2022'!K19-'2012-2022'!X$2)/'2012-2022'!X$3 -> 0.12991002 | L18: =('2012-2022'!L19-'2012-2022'!Y$2)/'2012-2022'!Y$3 -> -0.14832563 | ... N18: =('2012-2022'!N19-'2012-2022'!AA$2)/'2012-2022'!AA$3 -> 1.1299635 | O18: =('2012-2022'!P19-'2012-2022'!AC$2)/'2012-2022'!AC$3 -> 1.024783
A19: Canada | B19: 2019 | C19: North America | D19: High income | E19: =('2012-2022'!E20-'2012-2022'!R$2)/'2012-2022'!R$3 -> 2.005685 | F19: =('2012-2022'!F20-'2012-2022'!S$2)/'2012-2022'!S$3 -> 0.84331349 | G19: =('2012-2022'!G20-'2012-2022'!T$2)/'2012-2022'!T$3 -> 0.56820454 | H19: =('2012-2022'!H20-'2012-2022'!U$2)/'2012-2022'!U$3 -> 1.9737677 | I19: =('2012-2022'!I20-'2012-2022'!V$2)/'2012-2022'!V$3 -> 1.8950838 | J19: =('2012-2022'!J20-'2012-2022'!W$2)/'2012-2022'!W$3 -> 0.46918934 | K19: =('2012-2022'!K20-'2012-2022'!X$2)/'2012-2022'!X$3 -> -0.07871697 | L19: =('2012-2022'!L20-'2012-2022'!Y$2)/'2012-2022'!Y$3 -> 1.0671118 | ... N19: =('2012-2022'!N20-'2012-2022'!AA$2)/'2012-2022'!AA$3 -> 1.3850476 | O19: =('2012-2022'!P20-'2012-2022'!AC$2)/'2012-2022'!AC$3 -> 1.0755321
A20: Canada | B20: 2020 | C20: North America | D20: High income | E20: =('2012-2022'!E21-'2012-2022'!R$2)/'2012-2022'!R$3 -> 1.1554145 | F20: =('2012-2022'!F21-'2012-2022'!S$2)/'2012-2022'!S$3 -> 0.88465066 | G20: =('2012-2022'!G21-'2012-2022'!T$2)/'2012-2022'!T$3 -> -0.1787701 | H20: =('2012-2022'!H21-'2012-2022'!U$2)/'2012-2022'!U$3 -> 1.5272779 | I20: =('2012-2022'!I21-'2012-2022'!V$2)/'2012-2022'!V$3 -> 0.84616872 | J20: =('2012-2022'!J21-'2012-2022'!W$2)/'2012-2022'!W$3 -> 0.36619424 | K20: =('2012-2022'!K21-'2012-2022'!X$2)/'2012-2022'!X$3 -> -0.34725367 | L20: =('2012-2022'!L21-'2012-2022'!Y$2)/'2012-2022'!Y$3 -> 0.73615589 | ... N20: =('2012-2022'!N21-'2012-2022'!AA$2)/'2012-2022'!AA$3 -> 0.26759042 | O20: =('2012-2022'!P21-'2012-2022'!AC$2)/'2012-2022'!AC$3 -> 0.96267267
A21: Canada | B21: 2021 | C21: North America | D21: High income | E21: =('2012-2022'!E22-'2012-2022'!R$2)/'2012-2022'!R$3 -> 2.4361704 | F21: =('2012-2022'!F22-'2012-2022'!S$2)/'2012-2022'!S$3 -> 1.1302186 | G21: =('2012-2022'!G22-'2012-2022'!T$2)/'2012-2022'!T$3 -> 0.33709489 | H21: =('2012-2022'!H22-'2012-2022'!U$2)/'2012-2022'!U$3 -> 2.6865321 | I21: =('2012-2022'!I22-'2012-2022'!V$2)/'2012-2022'!V$3 -> 2.1203592 | J21: =('2012-2022'!J22-'2012-2022'!W$2)/'2012-2022'!W$3 -> 0.65378926 | K21: =('2012-2022'!K22-'2012-2022'!X$2)/'2012-2022'!X$3 -> 0.014885195 | L21: =('2012-2022'!L22-'2012-2022'!Y$2)/'2012-2022'!Y$3 -> 0.79519376 | ... N21: =('2012-2022'!N22-'2012-2022'!AA$2)/'2012-2022'!AA$3 -> 1.597507 | O21: =('2012-2022'!P22-'2012-2022'!AC$2)/'2012-2022'!AC$3 -> 1.0114463
A22: Canada | B22: 2022 | C22: North America | D22: High income | E22: =('2012-2022'!E23-'2012-2022'!R$2)/'2012-2022'!R$3 -> 1.4739039 | F22: =('2012-2022'!F23-'2012-2022'!S$2)/'2012-2022'!S$3 -> 0.36549235 | G22: =('2012-2022'!G23-'2012-2022'!T$2)/'2012-2022'!T$3 -> 0.68128219 | H22: =('2012-2022'!H23-'2012-2022'!U$2)/'2012-2022'!U$3 -> 1.2993143 | I22: =('2012-2022'!I23-'2012-2022'!V$2)/'2012-2022'!V$3 -> 1.4605179 | J22: =('2012-2022'!J23-'2012-2022'!W$2)/'2012-2022'!W$3 -> 0.34754857 | K22: =('2012-2022'!K23-'2012-2022'!X$2)/'2012-2022'!X$3 -> -0.16781355 | L22: =('2012-2022'!L23-'2012-2022'!Y$2)/'2012-2022'!Y$3 -> 0.44137732 | ... N22: =('2012-2022'!N23-'2012-2022'!AA$2)/'2012-2022'!AA$3 -> 0.87263877 | O22: =('2012-2022'!P23-'2012-2022'!AC$2)/'2012-2022'!AC$3 -> 1.0121264
A23: Chile | B23: 2012 | C23: Latin America & Caribbean | D23: High income | E23: =('2012-2022'!E24-'2012-2022'!R$2)/'2012-2022'!R$3 -> 1.2593932 | F23: =('2012-2022'!F24-'2012-2022'!S$2)/'2012-2022'!S$3 -> 0.074904173 | G23: =('2012-2022'!G24-'2012-2022'!T$2)/'2012-2022'!T$3 -> -0.074798197 | H23: =('2012-2022'!H24-'2012-2022'!U$2)/'2012-2022'!U$3 -> 0.94626053 | I23: =('2012-2022'!I24-'2012-2022'!V$2)/'2012-2022'!V$3 -> 1.4022033 | J23: =('2012-2022'!J24-'2012-2022'!W$2)/'2012-2022'!W$3 -> 0.73891929 | K23: =('2012-2022'!K24-'2012-2022'!X$2)/'2012-2022'!X$3 -> 1.7189809 | L23: =('2012-2022'!L24-'2012-2022'!Y$2)/'2012-2022'!Y$3 -> 0.009473236 | ... N23: =('2012-2022'!N24-'2012-2022'!AA$2)/'2012-2022'!AA$3 -> 1.2497444 | O23: =('2012-2022'!P24-'2012-2022'!AC$2)/'2012-2022'!AC$3 -> 0.9054701
A24: Chile | B24: 2013 | C24: Latin America & Caribbean | D24: High income | E24: =('2012-2022'!E25-'2012-2022'!R$2)/'2012-2022'!R$3 -> 1.3411268 | F24: =('2012-2022'!F25-'2012-2022'!S$2)/'2012-2022'!S$3 -> -0.57093537 | G24: =('2012-2022'!G25-'2012-2022'!T$2)/'2012-2022'!T$3 -> -0.17630524 | H24: =('2012-2022'!H25-'2012-2022'!U$2)/'2012-2022'!U$3 -> 0.35703412 | I24: =('2012-2022'!I25-'2012-2022'!V$2)/'2012-2022'!V$3 -> 2.0894713 | J24: =('2012-2022'!J25-'2012-2022'!W$2)/'2012-2022'!W$3 -> 0.7142967 | K24: =('2012-2022'!K25-'2012-2022'!X$2)/'2012-2022'!X$3 -> 1.9047444 | L24: =('2012-2022'!L25-'2012-2022'!Y$2)/'2012-2022'!Y$3 -> 0.041083928 | ... N24: =('2012-2022'!N25-'2012-2022'!AA$2)/'2012-2022'!AA$3 -> 1.4668076 | O24: =('2012-2022'!P25-'2012-2022'!AC$2)/'2012-2022'!AC$3 -> 0.84776012
... A77: Greece | B77: 2022 | C77: Europe & Central Asia | D77: High income | E77: =('2012-2022'!E78-'2012-2022'!R$2)/'2012-2022'!R$3 -> -1.1941894 | F77: =('2012-2022'!F78-'2012-2022'!S$2)/'2012-2022'!S$3 -> 0.28603354 | G77: =('2012-2022'!G78-'2012-2022'!T$2)/'2012-2022'!T$3 -> -0.50523038 | H77: =('2012-2022'!H78-'2012-2022'!U$2)/'2012-2022'!U$3 -> -0.89195103 | I77: =('2012-2022'!I78-'2012-2022'!V$2)/'2012-2022'!V$3 -> -1.3083131 | J77: =('2012-2022'!J78-'2012-2022'!W$2)/'2012-2022'!W$3 -> 0.20613244 | K77: =('2012-2022'!K78-'2012-2022'!X$2)/'2012-2022'!X$3 -> -0.97373072 | L77: =('2012-2022'!L78-'2012-2022'!Y$2)/'2012-2022'!Y$3 -> -1.0548451 | ... N77: =('2012-2022'!N78-'2012-2022'!AA$2)/'2012-2022'!AA$3 -> -0.52553658 | O77: =('2012-2022'!P78-'2012-2022'!AC$2)/'2012-2022'!AC$3 -> -0.51033104
A78: Guatemala | B78: 2013 | C78: Latin America & Caribbean | D78: Upper-middle income | E78: =('2012-2022'!E80-'2012-2022'!R$2)/'2012-2022'!R$3 -> -0.27242671 | F78: =('2012-2022'!F80-'2012-2022'!S$2)/'2012-2022'!S$3 -> 0.69982972 | G78: =('2012-2022'!G80-'2012-2022'!T$2)/'2012-2022'!T$3 -> 0.99724842 | H78: =('2012-2022'!H80-'2012-2022'!U$2)/'2012-2022'!U$3 -> -0.45889198 | I78: =('2012-2022'!I80-'2012-2022'!V$2)/'2012-2022'!V$3 -> 0.006700222 | J78: =('2012-2022'!J80-'2012-2022'!W$2)/'2012-2022'!W$3 -> 1.3067067 | K78: =('2012-2022'!K80-'2012-2022'!X$2)/'2012-2022'!X$3 -> 1.3511228 | L78: =('2012-2022'!L80-'2012-2022'!Y$2)/'2012-2022'!Y$3 -> -0.74006965 | ... N78: =('2012-2022'!N80-'2012-2022'!AA$2)/'2012-2022'!AA$3 -> 0.8687476 | O78: =('2012-2022'!P80-'2012-2022'!AC$2)/'2012-2022'!AC$3 -> -1.6756767
A79: Guatemala | B79: 2014 | C79: Latin America & Caribbean | D79: Upper-middle income | E79: =('2012-2022'!E81-'2012-2022'!R$2)/'2012-2022'!R$3 -> 1.064724 | F79: =('2012-2022'!F81-'2012-2022'!S$2)/'2012-2022'!S$3 -> 1.628646 | G79: =('2012-2022'!G81-'2012-2022'!T$2)/'2012-2022'!T$3 -> 0.94367382 | H79: =('2012-2022'!H81-'2012-2022'!U$2)/'2012-2022'!U$3 -> 0.86430694 | I79: =('2012-2022'!I81-'2012-2022'!V$2)/'2012-2022'!V$3 -> 1.2560868 | J79: =('2012-2022'!J81-'2012-2022'!W$2)/'2012-2022'!W$3 -> 1.1086283 | K79: =('2012-2022'!K81-'2012-2022'!X$2)/'2012-2022'!X$3 -> 1.4921877 | L79: =('2012-2022'!L81-'2012-2022'!Y$2)/'2012-2022'!Y$3 -> -1.1943097 | ... N79: =('2012-2022'!N81-'2012-2022'!AA$2)/'2012-2022'!AA$3 -> 0.035878795 | O79: =('2012-2022'!P81-'2012-2022'!AC$2)/'2012-2022'!AC$3 -> -1.6343494
A80: Guatemala | B80: 2015 | C80: Latin America & Caribbean | D80: Upper-middle income | E80: =('2012-2022'!E82-'2012-2022'!R$2)/'2012-2022'!R$3 -> 0.69922142 | F80: =('2012-2022'!F82-'2012-2022'!S$2)/'2012-2022'!S$3 -> 1.8928074 | G80: =('2012-2022'!G82-'2012-2022'!T$2)/'2012-2022'!T$3 -> 0.77659936 | H80: =('2012-2022'!H82-'2012-2022'!U$2)/'2012-2022'!U$3 -> 0.69089191 | I80: =('2012-2022'!I82-'2012-2022'!V$2)/'2012-2022'!V$3 -> 0.74362322 | J80: =('2012-2022'!J82-'2012-2022'!W$2)/'2012-2022'!W$3 -> 0.7452044 | K80: =('2012-2022'!K82-'2012-2022'!X$2)/'2012-2022'!X$3 -> 1.3984782 | L80: =('2012-2022'!L82-'2012-2022'!Y$2)/'2012-2022'!Y$3 -> -0.85386357 | ... N80: =('2012-2022'!N82-'2012-2022'!AA$2)/'2012-2022'!AA$3 -> 0.19180734 | O80: =('2012-2022'!P82-'2012-2022'!AC$2)/'2012-2022'!AC$3 -> -1.5487026
A81: Guatemala | B81: 2016 | C81: Latin America & Caribbean | D81: Upper-middle income | E81: =('2012-2022'!E83-'2012-2022'!R$2)/'2012-2022'!R$3 -> 0.95774025 | F81: =('2012-2022'!F83-'2012-2022'!S$2)/'2012-2022'!S$3 -> 2.0239497 | G81: =('2012-2022'!G83-'2012-2022'!T$2)/'2012-2022'!T$3 -> 0.35547334 | H81: =('2012-2022'!H83-'2012-2022'!U$2)/'2012-2022'!U$3 -> 1.0859484 | I81: =('2012-2022'!I83-'2012-2022'!V$2)/'2012-2022'!V$3 -> 0.86331825 | J81: =('2012-2022'!J83-'2012-2022'!W$2)/'2012-2022'!W$3 -> 0.88265155 | K81: =('2012-2022'!K83-'2012-2022'!X$2)/'2012-2022'!X$3 -> 1.2891289 | L81: =('2012-2022'!L83-'2012-2022'!Y$2)/'2012-2022'!Y$3 -> -0.60282831 | ... N81: =('2012-2022'!N83-'2012-2022'!AA$2)/'2012-2022'!AA$3 -> 0.21339258 | O81: =('2012-2022'!P83-'2012-2022'!AC$2)/'2012-2022'!AC$3 -> -1.4877322
A82: Guatemala | B82: 2017 | C82: Latin America & Caribbean | D82: Upper-middle income | E82: =('2012-2022'!E84-'2012-2022'!R$2)/'2012-2022'!R$3 -> 1.64011 | F82: =('2012-2022'!F84-'2012-2022'!S$2)/'2012-2022'!S$3 -> 2.0651668 | G82: =('2012-2022'!G84-'2012-2022'!T$2)/'2012-2022'!T$3 -> 0.33027238 | H82: =('2012-2022'!H84-'2012-2022'!U$2)/'2012-2022'!U$3 -> 1.752079 | I82: =('2012-2022'!I84-'2012-2022'!V$2)/'2012-2022'!V$3 -> 1.5141184 | J82: =('2012-2022'!J84-'2012-2022'!W$2)/'2012-2022'!W$3 -> 1.136953 | K82: =('2012-2022'!K84-'2012-2022'!X$2)/'2012-2022'!X$3 -> 1.8082184 | L82: =('2012-2022'!L84-'2012-2022'!Y$2)/'2012-2022'!Y$3 -> 0.13390408 | ... N82: =('2012-2022'!N84-'2012-2022'!AA$2)/'2012-2022'!AA$3 -> 0.52867784 | O82: =('2012-2022'!P84-'2012-2022'!AC$2)/'2012-2022'!AC$3 -> -1.6076424
A83: Guatemala | B83: 2018 | C83: Latin America & Caribbean | D83: Upper-middle income | E83: =('2012-2022'!E85-'2012-2022'!R$2)/'2012-2022'!R$3 -> 2.079353 | F83: =('2012-2022'!F85-'2012-2022'!S$2)/'2012-2022'!S$3 -> 2.1428983 | G83: =('2012-2022'!G85-'2012-2022'!T$2)/'2012-2022'!T$3 -> 0.33439853 | H83: =('2012-2022'!H85-'2012-2022'!U$2)/'2012-2022'!U$3 -> 2.2094759 | I83: =('2012-2022'!I85-'2012-2022'!V$2)/'2012-2022'!V$3 -> 1.9073959 | J83: =('2012-2022'!J85-'2012-2022'!W$2)/'2012-2022'!W$3 -> 1.1947115 | K83: =('2012-2022'!K85-'2012-2022'!X$2)/'2012-2022'!X$3 -> 2.0499671 | L83: =('2012-2022'!L85-'2012-2022'!Y$2)/'2012-2022'!Y$3 -> 0.086453632 | ... N83: =('2012-2022'!N85-'2012-2022'!AA$2)/'2012-2022'!AA$3 -> 0.61100859 | O83: =('2012-2022'!P85-'2012-2022'!AC$2)/'2012-2022'!AC$3 -> -1.5311483
A84: Guatemala | B84: 2019 | C84: Latin America & Caribbean | D84: Upper-middle income | E84: =('2012-2022'!E86-'2012-2022'!R$2)/'2012-2022'!R$3 -> 1.9399991 | F84: =('2012-2022'!F86-'2012-2022'!S$2)/'2012-2022'!S$3 -> 1.6384625 | G84: =('2012-2022'!G86-'2012-2022'!T$2)/'2012-2022'!T$3 -> 1.2947242 | H84: =('2012-2022'!H86-'2012-2022'!U$2)/'2012-2022'!U$3 -> 1.5120594 | I84: =('2012-2022'!I86-'2012-2022'!V$2)/'2012-2022'!V$3 -> 2.2574325 | J84: =('2012-2022'!J86-'2012-2022'!W$2)/'2012-2022'!W$3 -> 2.2593391 | K84: =('2012-2022'!K86-'2012-2022'!X$2)/'2012-2022'!X$3 -> 2.2337698 | L84: =('2012-2022'!L86-'2012-2022'!Y$2)/'2012-2022'!Y$3 -> 2.1287703 | ... N84: =('2012-2022'!N86-'2012-2022'!AA$2)/'2012-2022'!AA$3 -> 1.3954923 | O84: =('2012-2022'!P86-'2012-2022'!AC$2)/'2012-2022'!AC$3 -> -1.5719025
A85: Guatemala | B85: 2020 | C85: Latin America & Caribbean | D85: Upper-middle income | E85: =('2012-2022'!E87-'2012-2022'!R$2)/'2012-2022'!R$3 -> 2.5460324 | F85: =('2012-2022'!F87-'2012-2022'!S$2)/'2012-2022'!S$3 -> 2.5764484 | G85: =('2012-2022'!G87-'2012-2022'!T$2)/'2012-2022'!T$3 -> 0.46892984 | H85: =('2012-2022'!H87-'2012-2022'!U$2)/'2012-2022'!U$3 -> 2.9776575 | I85: =('2012-2022'!I87-'2012-2022'!V$2)/'2012-2022'!V$3 -> 2.0879085 | J85: =('2012-2022'!J87-'2012-2022'!W$2)/'2012-2022'!W$3 -> 1.9985877 | K85: =('2012-2022'!K87-'2012-2022'!X$2)/'2012-2022'!X$3 -> 2.1090682 | L85: =('2012-2022'!L87-'2012-2022'!Y$2)/'2012-2022'!Y$3 -> 2.3631018 | ... N85: =('2012-2022'!N87-'2012-2022'!AA$2)/'2012-2022'!AA$3 -> 1.1094482 | O85: =('2012-2022'!P87-'2012-2022'!AC$2)/'2012-2022'!AC$3 -> -1.5139811
A86: Guatemala | B86: 2021 | C86: Latin America & Caribbean | D86: Upper-middle income | E86: =('2012-2022'!E88-'2012-2022'!R$2)/'2012-2022'!R$3 -> 2.4182581 | F86: =('2012-2022'!F88-'2012-2022'!S$2)/'2012-2022'!S$3 -> 1.8849839 | G86: =('2012-2022'!G88-'2012-2022'!T$2)/'2012-2022'!T$3 -> 0.73324581 | H86: =('2012-2022'!H88-'2012-2022'!U$2)/'2012-2022'!U$3 -> 2.3663102 | I86: =('2012-2022'!I88-'2012-2022'!V$2)/'2012-2022'!V$3 -> 2.361361 | J86: =('2012-2022'!J88-'2012-2022'!W$2)/'2012-2022'!W$3 -> 2.1643903 | K86: =('2012-2022'!K88-'2012-2022'!X$2)/'2012-2022'!X$3 -> 1.8298904 | L86: =('2012-2022'!L88-'2012-2022'!Y$2)/'2012-2022'!Y$3 -> 2.3426591 | ... N86: =('2012-2022'!N88-'2012-2022'!AA$2)/'2012-2022'!AA$3 -> 1.5111771 | O86: =('2012-2022'!P88-'2012-2022'!AC$2)/'2012-2022'!AC$3 -> -1.5251907
A87: Guatemala | B87: 2022 | C87: Latin America & Caribbean | D87: Upper-middle income | E87: =('2012-2022'!E89-'2012-2022'!R$2)/'2012-2022'!R$3 -> 2.9718736 | F87: =('2012-2022'!F89-'2012-2022'!S$2)/'2012-2022'!S$3 -> 2.2780699 | G87: =('2012-2022'!G89-'2012-2022'!T$2)/'2012-2022'!T$3 -> 1.0847546 | H87: =('2012-2022'!H89-'2012-2022'!U$2)/'2012-2022'!U$3 -> 3.0152464 | I87: =('2012-2022'!I89-'2012-2022'!V$2)/'2012-2022'!V$3 -> 2.7936323 | J87: =('2012-2022'!J89-'2012-2022'!W$2)/'2012-2022'!W$3 -> 2.2685875 | K87: =('2012-2022'!K89-'2012-2022'!X$2)/'2012-2022'!X$3 -> 1.9028479 | L87: =('2012-2022'!L89-'2012-2022'!Y$2)/'2012-2022'!Y$3 -> 2.3739482 | ... N87: =('2012-2022'!N89-'2012-2022'!AA$2)/'2012-2022'!AA$3 -> 1.458673 | O87: =('2012-2022'!P89-'2012-2022'!AC$2)/'2012-2022'!AC$3 -> -1.519796
A88: India | B88: 2013 | C88: South Asia | D88: Lower-middle income | E88: =('2012-2022'!E91-'2012-2022'!R$2)/'2012-2022'!R$3 -> -0.42217527 | F88: =('2012-2022'!F91-'2012-2022'!S$2)/'2012-2022'!S$3 -> 0.42646192 | G88: =('2012-2022'!G91-'2012-2022'!T$2)/'2012-2022'!T$3 -> 1.2189589 | H88: =('2012-2022'!H91-'2012-2022'!U$2)/'2012-2022'!U$3 -> -0.57917919 | I88: =('2012-2022'!I91-'2012-2022'!V$2)/'2012-2022'!V$3 -> -0.21644114 | J88: =('2012-2022'!J91-'2012-2022'!W$2)/'2012-2022'!W$3 -> 0.38035108 | K88: =('2012-2022'!K91-'2012-2022'!X$2)/'2012-2022'!X$3 -> 0.24289868 | L88: =('2012-2022'!L91-'2012-2022'!Y$2)/'2012-2022'!Y$3 -> -0.25242666 | ... N88: =('2012-2022'!N91-'2012-2022'!AA$2)/'2012-2022'!AA$3 -> -0.20921929 | O88: =('2012-2022'!P91-'2012-2022'!AC$2)/'2012-2022'!AC$3 -> -1.5079036
A89: India | B89: 2014 | C89: South Asia | D89: Lower-middle income | E89: =('2012-2022'!E92-'2012-2022'!R$2)/'2012-2022'!R$3 -> -0.90294781 | F89: =('2012-2022'!F92-'2012-2022'!S$2)/'2012-2022'!S$3 -> 0.88919965 | G89: =('2012-2022'!G92-'2012-2022'!T$2)/'2012-2022'!T$3 -> 0.90031458 | H89: =('2012-2022'!H92-'2012-2022'!U$2)/'2012-2022'!U$3 -> -0.7981449 | I89: =('2012-2022'!I92-'2012-2022'!V$2)/'2012-2022'!V$3 -> -0.87354448 | J89: =('2012-2022'!J92-'2012-2022'!W$2)/'2012-2022'!W$3 -> -1.276385 | K89: =('2012-2022'!K92-'2012-2022'!X$2)/'2012-2022'!X$3 -> -0.96538892 | L89: =('2012-2022'!L92-'2012-2022'!Y$2)/'2012-2022'!Y$3 -> -1.4885146 | ... N89: =('2012-2022'!N92-'2012-2022'!AA$2)/'2012-2022'!AA$3 -> -0.36632698 | O89: =('2012-2022'!P92-'2012-2022'!AC$2)/'2012-2022'!AC$3 -> -1.5187904
A90: India | B90: 2015 | C90: South Asia | D90: Lower-middle income | E90: =('2012-2022'!E93-'2012-2022'!R$2)/'2012-2022'!R$3 -> -0.49125889 | F90: =('2012-2022'!F93-'2012-2022'!S$2)/'2012-2022'!S$3 -> 0.72396312 | G90: =('2012-2022'!G93-'2012-2022'!T$2)/'2012-2022'!T$3 -> -0.12982531 | H90: =('2012-2022'!H93-'2012-2022'!U$2)/'2012-2022'!U$3 -> -0.36776839 | I90: =('2012-2022'!I93-'2012-2022'!V$2)/'2012-2022'!V$3 -> -0.5037139 | J90: =('2012-2022'!J93-'2012-2022'!W$2)/'2012-2022'!W$3 -> -1.1771021 | K90: =('2012-2022'!K93-'2012-2022'!X$2)/'2012-2022'!X$3 -> -0.67687865 | L90: =('2012-2022'!L93-'2012-2022'!Y$2)/'2012-2022'!Y$3 -> -0.32926519 | ... N90: =('2012-2022'!N93-'2012-2022'!AA$2)/'2012-2022'!AA$3 -> -0.43572433 | O90: =('2012-2022'!P93-'2012-2022'!AC$2)/'2012-2022'!AC$3 -> -1.4551975
A91: India | B91: 2016 | C91: South Asia | D91: Lower-middle income | E91: =('2012-2022'!E94-'2012-2022'!R$2)/'2012-2022'!R$3 -> -0.44566984 | F91: =('2012-2022'!F94-'2012-2022'!S$2)/'2012-2022'!S$3 -> 1.2219632 | G91: =('2012-2022'!G94-'2012-2022'!T$2)/'2012-2022'!T$3 -> -0.18881362 | H91: =('2012-2022'!H94-'2012-2022'!U$2)/'2012-2022'!U$3 -> -0.20234647 | I91: =('2012-2022'!I94-'2012-2022'!V$2)/'2012-2022'!V$3 -> -0.55639159 | J91: =('2012-2022'!J94-'2012-2022'!W$2)/'2012-2022'!W$3 -> -0.64320141 | K91: =('2012-2022'!K94-'2012-2022'!X$2)/'2012-2022'!X$3 -> -0.19617982 | L91: =('2012-2022'!L94-'2012-2022'!Y$2)/'2012-2022'!Y$3 -> -0.66928244 | ... N91: =('2012-2022'!N94-'2012-2022'!AA$2)/'2012-2022'!AA$3 -> -0.028513639 | O91: =('2012-2022'!P94-'2012-2022'!AC$2)/'2012-2022'!AC$3 -> -1.3587128
A92: India | B92: 2017 | C92: South Asia | D92: Lower-middle income | E92: =('2012-2022'!E95-'2012-2022'!R$2)/'2012-2022'!R$3 -> -0.68551512 | F92: =('2012-2022'!F95-'2012-2022'!S$2)/'2012-2022'!S$3 -> 1.4360395 | G92: =('2012-2022'!G95-'2012-2022'!T$2)/'2012-2022'!T$3 -> -0.72721162 | H92: =('2012-2022'!H95-'2012-2022'!U$2)/'2012-2022'!U$3 -> -0.30213691 | I92: =('2012-2022'!I95-'2012-2022'!V$2)/'2012-2022'!V$3 -> -0.89158113 | J92: =('2012-2022'!J95-'2012-2022'!W$2)/'2012-2022'!W$3 -> -0.81143845 | K92: =('2012-2022'!K95-'2012-2022'!X$2)/'2012-2022'!X$3 -> -0.62637411 | L92: =('2012-2022'!L95-'2012-2022'!Y$2)/'2012-2022'!Y$3 -> -0.86997064 | ... N92: =('2012-2022'!N95-'2012-2022'!AA$2)/'2012-2022'!AA$3 -> 0.0074879494 | O92: =('2012-2022'!P95-'2012-2022'!AC$2)/'2012-2022'!AC$3 -> -1.3112556
...

Sheet S2019-2022
A1: Country | B1: Year | C1: Region | D1: Income Group | E1: TEA_18_34 | F1: Teaap1 | G1: Teaap2 | H1: Teaac1 | I1: Teaac2 | J1: Suskil | K1: Futsup | L1: Knoent | M1: Frfail | N1: Opport | O1: Nbstat | P1: RQ
A2: Canada | B2: 2019 | C2: North America | D2: High income | E2: =('2019-2022'!E2-'2019-2022'!R$2)/'2019-2022'!R$3 -> 1.7958544 | F2: =('2019-2022'!F2-'2019-2022'!S$2)/'2019-2022'!S$3 -> 0.58609374 | G2: =('2019-2022'!G2-'2019-2022'!T$2)/'2019-2022'!T$3 -> 0.22405915 | H2: =('2019-2022'!H2-'2019-2022'!U$2)/'2019-2022'!U$3 -> 1.6773182 | I2: =('2019-2022'!I2-'2019-2022'!V$2)/'2019-2022'!V$3 -> 1.8062895 | J2: =('2019-2022'!J2-'2019-2022'!W$2)/'2019-2022'!W$3 -> -0.11045833 | K2: =('2019-2022'!K2-'2019-2022'!X$2)/'2019-2022'!X$3 -> -0.36791177 | L2: =('2019-2022'!L2-'2019-2022'!Y$2)/'2019-2022'!Y$3 -> 0.23137476 | ... P2: =('2019-2022'!P2-'2019-2022'!AC$2)/'2019-2022'!AC$3 -> 1.3893188
A3: Canada | B3: 2020 | C3: North America | D3: High income | E3: =('2019-2022'!E3-'2019-2022'!R$2)/'2019-2022'!R$3 -> 1.0001682 | F3: =('2019-2022'!F3-'2019-2022'!S$2)/'2019-2022'!S$3 -> 0.62270172 | G3: =('2019-2022'!G3-'2019-2022'!T$2)/'2019-2022'!T$3 -> -0.39959859 | H3: =('2019-2022'!H3-'2019-2022'!U$2)/'2019-2022'!U$3 -> 1.2679239 | I3: =('2019-2022'!I3-'2019-2022'!V$2)/'2019-2022'!V$3 -> 0.78911848 | J3: =('2019-2022'!J3-'2019-2022'!W$2)/'2019-2022'!W$3 -> -0.19137817 | K3: =('2019-2022'!K3-'2019-2022'!X$2)/'2019-2022'!X$3 -> -0.5888011 | L3: =('2019-2022'!L3-'2019-2022'!Y$2)/'2019-2022'!Y$3 -> -0.048201589 | ... P3: =('2019-2022'!P3-'2019-2022'!AC$2)/'2019-2022'!AC$3 -> 1.2672546
A4: Canada | B4: 2021 | C4: North America | D4: High income | E4: =('2019-2022'!E4-'2019-2022'!R$2)/'2019-2022'!R$3 -> 2.1987042 | F4: =('2019-2022'!F4-'2019-2022'!S$2)/'2019-2022'!S$3 -> 0.84017536 | G4: =('2019-2022'!G4-'2019-2022'!T$2)/'2019-2022'!T$3 -> 0.031103036 | H4: =('2019-2022'!H4-'2019-2022'!U$2)/'2019-2022'!U$3 -> 2.3308644 | I4: =('2019-2022'!I4-'2019-2022'!V$2)/'2019-2022'!V$3 -> 2.0247473 | J4: =('2019-2022'!J4-'2019-2022'!W$2)/'2019-2022'!W$3 -> 0.034575736 | K4: =('2019-2022'!K4-'2019-2022'!X$2)/'2019-2022'!X$3 -> -0.29091775 | L4: =('2019-2022'!L4-'2019-2022'!Y$2)/'2019-2022'!Y$3 -> 0.0016708999 | ... P4: =('2019-2022'!P4-'2019-2022'!AC$2)/'2019-2022'!AC$3 -> 1.3200062
A5: Canada | B5: 2022 | C5: North America | D5: High income | E5: =('2019-2022'!E5-'2019-2022'!R$2)/'2019-2022'!R$3 -> 1.2982117 | F5: =('2019-2022'!F5-'2019-2022'!S$2)/'2019-2022'!S$3 -> 0.16293787 | G5: =('2019-2022'!G5-'2019-2022'!T$2)/'2019-2022'!T$3 -> 0.31846899 | H5: =('2019-2022'!H5-'2019-2022'!U$2)/'2019-2022'!U$3 -> 1.0589001 | I5: =('2019-2022'!I5-'2019-2022'!V$2)/'2019-2022'!V$3 -> 1.3848752 | J5: =('2019-2022'!J5-'2019-2022'!W$2)/'2019-2022'!W$3 -> -0.20602746 | K5: =('2019-2022'!K5-'2019-2022'!X$2)/'2019-2022'!X$3 -> -0.44119964 | L5: =('2019-2022'!L5-'2019-2022'!Y$2)/'2019-2022'!Y$3 -> -0.29721701 | ... P5: =('2019-2022'!P5-'2019-2022'!AC$2)/'2019-2022'!AC$3 -> 1.3207418
A6: Colombia | B6: 2019 | C6: Latin America & Caribbean | D6: Upper-middle income | E6: =('2019-2022'!E6-'2019-2022'!R$2)/'2019-2022'!R$3 -> 1.5368991 | F6: =('2019-2022'!F6-'2019-2022'!S$2)/'2019-2022'!S$3 -> 0.61103549 | G6: =('2019-2022'!G6-'2019-2022'!T$2)/'2019-2022'!T$3 -> -0.26080119 | H6: =('2019-2022'!H6-'2019-2022'!U$2)/'2019-2022'!U$3 -> 1.5878682 | I6: =('2019-2022'!I6-'2019-2022'!V$2)/'2019-2022'!V$3 -> 1.4524705 | J6: =('2019-2022'!J6-'2019-2022'!W$2)/'2019-2022'!W$3 -> 0.95161129 | K6: =('2019-2022'!K6-'2019-2022'!X$2)/'2019-2022'!X$3 -> 0.94284229 | L6: =('2019-2022'!L6-'2019-2022'!Y$2)/'2019-2022'!Y$3 -> 1.0003372 | ... P6: =('2019-2022'!P6-'2019-2022'!AC$2)/'2019-2022'!AC$3 -> -0.58274638
A7: Colombia | B7: 2020 | C7: Latin America & Caribbean | D7: Upper-middle income | E7: =('2019-2022'!E7-'2019-2022'!R$2)/'2019-2022'!R$3 -> 2.7601598 | F7: =('2019-2022'!F7-'2019-2022'!S$2)/'2019-2022'!S$3 -> 0.58174737 | G7: =('2019-2022'!G7-'2019-2022'!T$2)/'2019-2022'!T$3 -> -0.10565463 | H7: =('2019-2022'!H7-'2019-2022'!U$2)/'2019-2022'!U$3 -> 2.621873 | I7: =('2019-2022'!I7-'2019-2022'!V$2)/'2019-2022'!V$3 -> 2.7512574 | J7: =('2019-2022'!J7-'2019-2022'!W$2)/'2019-2022'!W$3 -> 0.43516391 | K7: =('2019-2022'!K7-'2019-2022'!X$2)/'2019-2022'!X$3 -> 1.0105369 | L7: =('2019-2022'!L7-'2019-2022'!Y$2)/'2019-2022'!Y$3 -> 1.0253921 | ... P7: =('2019-2022'!P7-'2019-2022'!AC$2)/'2019-2022'!AC$3 -> -0.67996329
A8: Colombia | B8: 2022 | C8: Latin America & Caribbean | D8: Upper-middle income | E8: =('2019-2022'!E9-'2019-2022'!R$2)/'2019-2022'!R$3 -> 1.9174025 | F8: =('2019-2022'!F9-'2019-2022'!S$2)/'2019-2022'!S$3 -> -0.22388903 | G8: =('2019-2022'!G9-'2019-2022'!T$2)/'2019-2022'!T$3 -> -0.085823281 | H8: =('2019-2022'!H9-'2019-2022'!U$2)/'2019-2022'!U$3 -> 1.2792832 | I8: =('2019-2022'!I9-'2019-2022'!V$2)/'2019-2022'!V$3 -> 2.2592224 | J8: =('2019-2022'!J9-'2019-2022'!W$2)/'2019-2022'!W$3 -> 0.55536654 | K8: =('2019-2022'!K9-'2019-2022'!X$2)/'2019-2022'!X$3 -> -0.045969871 | L8: =('2019-2022'!L9-'2019-2022'!Y$2)/'2019-2022'!Y$3 -> 0.81635842 | ... P8: =('2019-2022'!P9-'2019-2022'!AC$2)/'2019-2022'!AC$3 -> -0.64517772
A9: Croatia | B9: 2019 | C9: Europe & Central Asia | D9: High income | E9: =('2019-2022'!E10-'2019-2022'!R$2)/'2019-2022'!R$3 -> 0.24739207 | F9: =('2019-2022'!F10-'2019-2022'!S$2)/'2019-2022'!S$3 -> 0.20286515 | G9: =('2019-2022'!G10-'2019-2022'!T$2)/'2019-2022'!T$3 -> 0.53846939 | H9: =('2019-2022'!H10-'2019-2022'!U$2)/'2019-2022'!U$3 -> 0.13252524 | I9: =('2019-2022'!I10-'2019-2022'!V$2)/'2019-2022'!V$3 -> 0.30626054 | J9: =('2019-2022'!J10-'2019-2022'!W$2)/'2019-2022'!W$3 -> 0.87102134 | K9: =('2019-2022'!K10-'2019-2022'!X$2)/'2019-2022'!X$3 -> -0.094410822 | L9: =('2019-2022'!L10-'2019-2022'!Y$2)/'2019-2022'!Y$3 -> 0.97884747 | ... P9: =('2019-2022'!P10-'2019-2022'!AC$2)/'2019-2022'!AC$3 -> -0.37545923
A10: Croatia | B10: 2020 | C10: Europe & Central Asia | D10: High income | E10: =('2019-2022'!E11-'2019-2022'!R$2)/'2019-2022'!R$3 -> 0.60718258 | F10: =('2019-2022'!F11-'2019-2022'!S$2)/'2019-2022'!S$3 -> -0.11149741 | G10: =('2019-2022'!G11-'2019-2022'!T$2)/'2019-2022'!T$3 -> 0.59851265 | H10: =('2019-2022'!H11-'2019-2022'!U$2)/'2019-2022'!U$3 -> 0.22374382 | I10: =('2019-2022'!I11-'2019-2022'!V$2)/'2019-2022'!V$3 -> 0.81585718 | J10: =('2019-2022'!J11-'2019-2022'!W$2)/'2019-2022'!W$3 -> 1.130193 | K10: =('2019-2022'!K11-'2019-2022'!X$2)/'2019-2022'!X$3 -> 0.20794566 | L10: =('2019-2022'!L11-'2019-2022'!Y$2)/'2019-2022'!Y$3 -> 1.0829401 | ... P10: =('2019-2022'!P11-'2019-2022'!AC$2)/'2019-2022'!AC$3 -> -0.62429562
A11: Croatia | B11: 2021 | C11: Europe & Central Asia | D11: High income | E11: =('2019-2022'!E12-'2019-2022'!R$2)/'2019-2022'!R$3 -> 0.48938569 | F11: =('2019-2022'!F12-'2019-2022'!S$2)/'2019-2022'!S$3 -> -0.30475645 | G11: =('2019-2022'!G12-'2019-2022'!T$2)/'2019-2022'!T$3 -> 0.60589607 | H11: =('2019-2022'!H12-'2019-2022'!U$2)/'2019-2022'!U$3 -> -0.033489408 | I11: =('2019-2022'!I12-'2019-2022'!V$2)/'2019-2022'!V$3 -> 0.81728113 | J11: =('2019-2022'!J12-'2019-2022'!W$2)/'2019-2022'!W$3 -> 0.86250341 | K11: =('2019-2022'!K12-'2019-2022'!X$2)/'2019-2022'!X$3 -> 0.049823113 | L11: =('2019-2022'!L12-'2019-2022'!Y$2)/'2019-2022'!Y$3 -> 1.0962084 | ... P11: =('2019-2022'!P12-'2019-2022'!AC$2)/'2019-2022'!AC$3 -> -0.44749872
A12: Croatia | B12: 2022 | C12: Europe & Central Asia | D12: High income | E12: =('2019-2022'!E13-'2019-2022'!R$2)/'2019-2022'!R$3 -> 0.90451947 | F12: =('2019-2022'!F13-'2019-2022'!S$2)/'2019-2022'!S$3 -> -0.89334962 | G12: =('2019-2022'!G13-'2019-2022'!T$2)/'2019-2022'!T$3 -> 1.0588244 | H12: =('2019-2022'!H13-'2019-2022'!U$2)/'2019-2022'!U$3 -> 0.067297084 | I12: =('2019-2022'!I13-'2019-2022'!V$2)/'2019-2022'!V$3 -> 1.1960149 | J12: =('2019-2022'!J13-'2019-2022'!W$2)/'2019-2022'!W$3 -> 1.0361616 | K12: =('2019-2022'!K13-'2019-2022'!X$2)/'2019-2022'!X$3 -> -0.043137584 | L12: =('2019-2022'!L13-'2019-2022'!Y$2)/'2019-2022'!Y$3 -> 0.9970423 | ... P12: =('2019-2022'!P13-'2019-2022'!AC$2)/'2019-2022'!AC$3 -> -0.49164889
A13: Cyprus | B13: 2019 | C13: Europe & Central Asia | D13: High income | E13: =('2019-2022'!E14-'2019-2022'!R$2)/'2019-2022'!R$3 -> 0.0068272761 | F13: =('2019-2022'!F14-'2019-2022'!S$2)/'2019-2022'!S$3 -> -0.26503244 | G13: =('2019-2022'!G14-'2019-2022'!T$2)/'2019-2022'!T$3 -> 0.36767907 | H13: =('2019-2022'!H14-'2019-2022'!U$2)/'2019-2022'!U$3 -> -0.23080698 | I13: =('2019-2022'!I14-'2019-2022'!V$2)/'2019-2022'!V$3 -> 0.15029029 | J13: =('2019-2022'!J14-'2019-2022'!W$2)/'2019-2022'!W$3 -> -0.017582737 | K13: =('2019-2022'!K14-'2019-2022'!X$2)/'2019-2022'!X$3 -> -0.14134245 | L13: =('2019-2022'!L14-'2019-2022'!Y$2)/'2019-2022'!Y$3 -> 0.29060138 | ... P13: =('2019-2022'!P14-'2019-2022'!AC$2)/'2019-2022'!AC$3 -> 0.51486495
A14: Cyprus | B14: 2020 | C14: Europe & Central Asia | D14: High income | E14: =('2019-2022'!E15-'2019-2022'!R$2)/'2019-2022'!R$3 -> -0.63575325 | F14: =('2019-2022'!F15-'2019-2022'!S$2)/'2019-2022'!S$3 -> -0.91104184 | G14: =('2019-2022'!G15-'2019-2022'!T$2)/'2019-2022'!T$3 -> 0.006687531 | H14: =('2019-2022'!H15-'2019-2022'!U$2)/'2019-2022'!U$3 -> -0.88389191 | I14: =('2019-2022'!I15-'2019-2022'!V$2)/'2019-2022'!V$3 -> -0.4494126 | J14: =('2019-2022'!J15-'2019-2022'!W$2)/'2019-2022'!W$3 -> -0.021888706 | K14: =('2019-2022'!K15-'2019-2022'!X$2)/'2019-2022'!X$3 -> -0.28052129 | L14: =('2019-2022'!L15-'2019-2022'!Y$2)/'2019-2022'!Y$3 -> 1.1055114 | ... P14: =('2019-2022'!P15-'2019-2022'!AC$2)/'2019-2022'!AC$3 -> 0.3222827
A15: Cyprus | B15: 2021 | C15: Europe & Central Asia | D15: High income | E15: =('2019-2022'!E16-'2019-2022'!R$2)/'2019-2022'!R$3 -> -0.80898777 | F15: =('2019-2022'!F16-'2019-2022'!S$2)/'2019-2022'!S$3 -> -1.2230953 | G15: =('2019-2022'!G16-'2019-2022'!T$2)/'2019-2022'!T$3 -> 0.11054683 | H15: =('2019-2022'!H16-'2019-2022'!U$2)/'2019-2022'!U$3 -> -1.0984602 | I15: =('2019-2022'!I16-'2019-2022'!V$2)/'2019-2022'!V$3 -> -0.59491133 | J15: =('2019-2022'!J16-'2019-2022'!W$2)/'2019-2022'!W$3 -> 0.38377277 | K15: =('2019-2022'!K16-'2019-2022'!X$2)/'2019-2022'!X$3 -> -0.61542631 | L15: =('2019-2022'!L16-'2019-2022'!Y$2)/'2019-2022'!Y$3 -> 1.4301585 | ... P15: =('2019-2022'!P16-'2019-2022'!AC$2)/'2019-2022'!AC$3 -> 0.25506734
A16: Cyprus | B16: 2022 | C16: Europe & Central Asia | D16: High income | E16: =('2019-2022'!E17-'2019-2022'!R$2)/'2019-2022'!R$3 -> -0.24935442 | F16: =('2019-2022'!F17-'2019-2022'!S$2)/'2019-2022'!S$3 -> 0.54815456 | G16: =('2019-2022'!G17-'2019-2022'!T$2)/'2019-2022'!T$3 -> 0.58082193 | H16: =('2019-2022'!H17-'2019-2022'!U$2)/'2019-2022'!U$3 -> -0.18009425 | I16: =('2019-2022'!I17-'2019-2022'!V$2)/'2019-2022'!V$3 -> -0.27929614 | J16: =('2019-2022'!J17-'2019-2022'!W$2)/'2019-2022'!W$3 -> -0.39302631 | K16: =('2019-2022'!K17-'2019-2022'!X$2)/'2019-2022'!X$3 -> -0.37883072 | L16: =('2019-2022'!L17-'2019-2022'!Y$2)/'2019-2022'!Y$3 -> 2.0684011 | ... P16: =('2019-2022'!P17-'2019-2022'!AC$2)/'2019-2022'!AC$3 -> 0.098211878
A17: Egypt | B17: 2019 | C17: Middle East & North Africa | D17: Lower-middle income | E17: =('2019-2022'!E18-'2019-2022'!R$2)/'2019-2022'!R$3 -> -0.8451192 | F17: =('2019-2022'!F18-'2019-2022'!S$2)/'2019-2022'!S$3 -> 2.7545574 | G17: =('2019-2022'!G18-'2019-2022'!T$2)/'2019-2022'!T$3 -> -0.17696691 | H17: =('2019-2022'!H18-'2019-2022'!U$2)/'2019-2022'!U$3 -> -0.5720242 | I17: =('2019-2022'!I18-'2019-2022'!V$2)/'2019-2022'!V$3 -> -0.98023124 | J17: =('2019-2022'!J18-'2019-2022'!W$2)/'2019-2022'!W$3 -> 0.60272717 | K17: =('2019-2022'!K18-'2019-2022'!X$2)/'2019-2022'!X$3 -> 2.2408228 | L17: =('2019-2022'!L18-'2019-2022'!Y$2)/'2019-2022'!Y$3 -> 0.019654573 | ... P17: =('2019-2022'!P18-'2019-2022'!AC$2)/'2019-2022'!AC$3 -> -1.8543569
A18: Egypt | B18: 2020 | C18: Middle East & North Africa | D18: Lower-middle income | E18: =('2019-2022'!E19-'2019-2022'!R$2)/'2019-2022'!R$3 -> -0.25625364 | F18: =('2019-2022'!F19-'2019-2022'!S$2)/'2019-2022'!S$3 -> 2.6576841 | G18: =('2019-2022'!G19-'2019-2022'!T$2)/'2019-2022'!T$3 -> -0.62072084 | H18: =('2019-2022'!H19-'2019-2022'!U$2)/'2019-2022'!U$3 -> 0.079131118 | I18: =('2019-2022'!I19-'2019-2022'!V$2)/'2019-2022'!V$3 -> -0.49282732 | J18: =('2019-2022'!J19-'2019-2022'!W$2)/'2019-2022'!W$3 -> -0.15749047 | K18: =('2019-2022'!K19-'2019-2022'!X$2)/'2019-2022'!X$3 -> 1.8612411 | L18: =('2019-2022'!L19-'2019-2022'!Y$2)/'2019-2022'!Y$3 -> -1.1290499 | ... P18: =('2019-2022'!P19-'2019-2022'!AC$2)/'2019-2022'!AC$3 -> -1.7629098
A19: Egypt | B19: 2021 | C19: Middle East & North Africa | D19: Lower-middle income | E19: =('2019-2022'!E20-'2019-2022'!R$2)/'2019-2022'!R$3 -> -0.47900938 | F19: =('2019-2022'!F20-'2019-2022'!S$2)/'2019-2022'!S$3 -> 2.3754849 | G19: =('2019-2022'!G20-'2019-2022'!T$2)/'2019-2022'!T$3 -> 0.035973192 | H19: =('2019-2022'!H20-'2019-2022'!U$2)/'2019-2022'!U$3 -> -0.30221308 | I19: =('2019-2022'!I20-'2019-2022'!V$2)/'2019-2022'!V$3 -> -0.5277421 | J19: =('2019-2022'!J20-'2019-2022'!W$2)/'2019-2022'!W$3 -> 0.50275292 | K19: =('2019-2022'!K20-'2019-2022'!X$2)/'2019-2022'!X$3 -> 1.8299989 | L19: =('2019-2022'!L20-'2019-2022'!Y$2)/'2019-2022'!Y$3 -> -1.40892 | ... P19: =('2019-2022'!P20-'2019-2022'!AC$2)/'2019-2022'!AC$3 -> -1.67391
... A45: Japan | B45: 2019 | C45: East Asia & Pacific | D45: High income | E45: =('2019-2022'!E46-'2019-2022'!R$2)/'2019-2022'!R$3 -> -1.0986766 | F45: =('2019-2022'!F46-'2019-2022'!S$2)/'2019-2022'!S$3 -> -0.92732772 | G45: =('2019-2022'!G46-'2019-2022'!T$2)/'2019-2022'!T$3 -> -1.0695938 | H45: =('2019-2022'!H46-'2019-2022'!U$2)/'2019-2022'!U$3 -> -1.0508137 | I45: =('2019-2022'!I46-'2019-2022'!V$2)/'2019-2022'!V$3 -> -1.0714224 | J45: =('2019-2022'!J46-'2019-2022'!W$2)/'2019-2022'!W$3 -> -3.0312946 | K45: =('2019-2022'!K46-'2019-2022'!X$2)/'2019-2022'!X$3 -> -1.243087 | L45: =('2019-2022'!L46-'2019-2022'!Y$2)/'2019-2022'!Y$3 -> -2.3318002 | ... P45: =('2019-2022'!P46-'2019-2022'!AC$2)/'2019-2022'!AC$3 -> 0.98956091
A46: Japan | B46: 2021 | C46: East Asia & Pacific | D46: High income | E46: =('2019-2022'!E48-'2019-2022'!R$2)/'2019-2022'!R$3 -> -1.0774656 | F46: =('2019-2022'!F48-'2019-2022'!S$2)/'2019-2022'!S$3 -> -1.0306645 | G46: =('2019-2022'!G48-'2019-2022'!T$2)/'2019-2022'!T$3 -> -1.5171132 | H46: =('2019-2022'!H48-'2019-2022'!U$2)/'2019-2022'!U$3 -> -1.0085133 | I46: =('2019-2022'!I48-'2019-2022'!V$2)/'2019-2022'!V$3 -> -1.0631421 | J46: =('2019-2022'!J48-'2019-2022'!W$2)/'2019-2022'!W$3 -> -3.1490584 | K46: =('2019-2022'!K48-'2019-2022'!X$2)/'2019-2022'!X$3 -> -1.2702993 | L46: =('2019-2022'!L48-'2019-2022'!Y$2)/'2019-2022'!Y$3 -> -2.1304295 | ... P46: =('2019-2022'!P48-'2019-2022'!AC$2)/'2019-2022'!AC$3 -> 0.99897501
A47: Japan | B47: 2022 | C47: East Asia & Pacific | D47: High income | E47: =('2019-2022'!E49-'2019-2022'!R$2)/'2019-2022'!R$3 -> -1.0754171 | F47: =('2019-2022'!F49-'2019-2022'!S$2)/'2019-2022'!S$3 -> -0.53496247 | G47: =('2019-2022'!G49-'2019-2022'!T$2)/'2019-2022'!T$3 -> -1.9944973 | H47: =('2019-2022'!H49-'2019-2022'!U$2)/'2019-2022'!U$3 -> -0.76199129 | I47: =('2019-2022'!I49-'2019-2022'!V$2)/'2019-2022'!V$3 -> -1.2251914 | J47: =('2019-2022'!J49-'2019-2022'!W$2)/'2019-2022'!W$3 -> -2.9691707 | K47: =('2019-2022'!K49-'2019-2022'!X$2)/'2019-2022'!X$3 -> -1.1184764 | L47: =('2019-2022'!L49-'2019-2022'!Y$2)/'2019-2022'!Y$3 -> -2.1047677 | ... P47: =('2019-2022'!P49-'2019-2022'!AC$2)/'2019-2022'!AC$3 -> 1.019533
A48: Latvia | B48: 2019 | C48: Europe & Central Asia | D48: High income | E48: =('2019-2022'!E50-'2019-2022'!R$2)/'2019-2022'!R$3 -> 0.91728697 | F48: =('2019-2022'!F50-'2019-2022'!S$2)/'2019-2022'!S$3 -> -0.463192 | G48: =('2019-2022'!G50-'2019-2022'!T$2)/'2019-2022'!T$3 -> 0.21072146 | H48: =('2019-2022'!H50-'2019-2022'!U$2)/'2019-2022'!U$3 -> 0.82160307 | I48: =('2019-2022'!I50-'2019-2022'!V$2)/'2019-2022'!V$3 -> 0.87637024 | J48: =('2019-2022'!J50-'2019-2022'!W$2)/'2019-2022'!W$3 -> -0.098872961 | K48: =('2019-2022'!K50-'2019-2022'!X$2)/'2019-2022'!X$3 -> 0.052001441 | L48: =('2019-2022'!L50-'2019-2022'!Y$2)/'2019-2022'!Y$3 -> -0.31383111 | ... P48: =('2019-2022'!P50-'2019-2022'!AC$2)/'2019-2022'!AC$3 -> 0.46517624
A49: Latvia | B49: 2020 | C49: Europe & Central Asia | D49: High income | E49: =('2019-2022'!E51-'2019-2022'!R$2)/'2019-2022'!R$3 -> 1.7112334 | F49: =('2019-2022'!F51-'2019-2022'!S$2)/'2019-2022'!S$3 -> 0.090667314 | G49: =('2019-2022'!G51-'2019-2022'!T$2)/'2019-2022'!T$3 -> 1.1169956 | H49: =('2019-2022'!H51-'2019-2022'!U$2)/'2019-2022'!U$3 -> 1.6659927 | I49: =('2019-2022'!I51-'2019-2022'!V$2)/'2019-2022'!V$3 -> 1.6187192 | J49: =('2019-2022'!J51-'2019-2022'!W$2)/'2019-2022'!W$3 -> -0.21224817 | K49: =('2019-2022'!K51-'2019-2022'!X$2)/'2019-2022'!X$3 -> -0.28139221 | L49: =('2019-2022'!L51-'2019-2022'!Y$2)/'2019-2022'!Y$3 -> -1.0024277 | ... P49: =('2019-2022'!P51-'2019-2022'!AC$2)/'2019-2022'!AC$3 -> 0.43473712
A50: Latvia | B50: 2021 | C50: Europe & Central Asia | D50: High income | E50: =('2019-2022'!E52-'2019-2022'!R$2)/'2019-2022'!R$3 -> 0.98755173 | F50: =('2019-2022'!F52-'2019-2022'!S$2)/'2019-2022'!S$3 -> 0.17702793 | G50: =('2019-2022'!G52-'2019-2022'!T$2)/'2019-2022'!T$3 -> -0.37769092 | H50: =('2019-2022'!H52-'2019-2022'!U$2)/'2019-2022'!U$3 -> 1.67613 | I50: =('2019-2022'!I52-'2019-2022'!V$2)/'2019-2022'!V$3 -> 0.59681447 | J50: =('2019-2022'!J52-'2019-2022'!W$2)/'2019-2022'!W$3 -> -0.34744166 | K50: =('2019-2022'!K52-'2019-2022'!X$2)/'2019-2022'!X$3 -> -0.16005834 | L50: =('2019-2022'!L52-'2019-2022'!Y$2)/'2019-2022'!Y$3 -> -0.7099029 | ... P50: =('2019-2022'!P52-'2019-2022'!AC$2)/'2019-2022'!AC$3 -> 0.6008718
A51: Latvia | B51: 2022 | C51: Europe & Central Asia | D51: High income | E51: =('2019-2022'!E53-'2019-2022'!R$2)/'2019-2022'!R$3 -> 0.87711193 | F51: =('2019-2022'!F53-'2019-2022'!S$2)/'2019-2022'!S$3 -> -0.61015453 | G51: =('2019-2022'!G53-'2019-2022'!T$2)/'2019-2022'!T$3 -> 0.26197653 | H51: =('2019-2022'!H53-'2019-2022'!U$2)/'2019-2022'!U$3 -> 0.48948443 | I51: =('2019-2022'!I53-'2019-2022'!V$2)/'2019-2022'!V$3 -> 0.98829681 | J51: =('2019-2022'!J53-'2019-2022'!W$2)/'2019-2022'!W$3 -> -0.30990978 | K51: =('2019-2022'!K53-'2019-2022'!X$2)/'2019-2022'!X$3 -> -0.22835961 | L51: =('2019-2022'!L53-'2019-2022'!Y$2)/'2019-2022'!Y$3 -> -0.91969789 | ... P51: =('2019-2022'!P53-'2019-2022'!AC$2)/'2019-2022'!AC$3 -> 0.40542156
A52: Morocco | B52: 2019 | C52: Middle East & North Africa | D52: Lower-middle income | E52: =('2019-2022'!E54-'2019-2022'!R$2)/'2019-2022'!R$3 -> -0.42941515 | F52: =('2019-2022'!F54-'2019-2022'!S$2)/'2019-2022'!S$3 -> 0.030069568 | G52: =('2019-2022'!G54-'2019-2022'!T$2)/'2019-2022'!T$3 -> 0.71993042 | H52: =('2019-2022'!H54-'2019-2022'!U$2)/'2019-2022'!U$3 -> -0.75398521 | I52: =('2019-2022'!I54-'2019-2022'!V$2)/'2019-2022'!V$3 -> 0.010358618 | J52: =('2019-2022'!J54-'2019-2022'!W$2)/'2019-2022'!W$3 -> 0.26925052 | K52: =('2019-2022'!K54-'2019-2022'!X$2)/'2019-2022'!X$3 -> 0.89542327 | L52: =('2019-2022'!L54-'2019-2022'!Y$2)/'2019-2022'!Y$3 -> -0.034788623 | ... P52: =('2019-2022'!P54-'2019-2022'!AC$2)/'2019-2022'!AC$3 -> -0.86168017
A53: Morocco | B53: 2020 | C53: Middle East & North Africa | D53: Lower-middle income | E53: =('2019-2022'!E55-'2019-2022'!R$2)/'2019-2022'!R$3 -> -0.76999988 | F53: =('2019-2022'!F55-'2019-2022'!S$2)/'2019-2022'!S$3 -> 0.74625862 | G53: =('2019-2022'!G55-'2019-2022'!T$2)/'2019-2022'!T$3 -> 1.6175146 | H53: =('2019-2022'!H55-'2019-2022'!U$2)/'2019-2022'!U$3 -> -0.90312792 | I53: =('2019-2022'!I55-'2019-2022'!V$2)/'2019-2022'!V$3 -> -0.50316314 | J53: =('2019-2022'!J55-'2019-2022'!W$2)/'2019-2022'!W$3 -> 0.33836739 | K53: =('2019-2022'!K55-'2019-2022'!X$2)/'2019-2022'!X$3 -> 1.3068365 | L53: =('2019-2022'!L55-'2019-2022'!Y$2)/'2019-2022'!Y$3 -> -0.63225835 | ... P53: =('2019-2022'!P55-'2019-2022'!AC$2)/'2019-2022'!AC$3 -> -0.8105145
A54: Morocco | B54: 2021 | C54: Middle East & North Africa | D54: Lower-middle income | E54: =('2019-2022'!E56-'2019-2022'!R$2)/'2019-2022'!R$3 -> -1.0488274 | F54: =('2019-2022'!F56-'2019-2022'!S$2)/'2019-2022'!S$3 -> 1.1575809 | G54: =('2019-2022'!G56-'2019-2022'!T$2)/'2019-2022'!T$3 -> 0.18332518 | H54: =('2019-2022'!H56-'2019-2022'!U$2)/'2019-2022'!U$3 -> -0.91869633 | I54: =('2019-2022'!I56-'2019-2022'!V$2)/'2019-2022'!V$3 -> -1.0300884 | J54: =('2019-2022'!J56-'2019-2022'!W$2)/'2019-2022'!W$3 -> 0.20837457 | K54: =('2019-2022'!K56-'2019-2022'!X$2)/'2019-2022'!X$3 -> 0.90429134 | L54: =('2019-2022'!L56-'2019-2022'!Y$2)/'2019-2022'!Y$3 -> -0.51909467 | ... P54: =('2019-2022'!P56-'2019-2022'!AC$2)/'2019-2022'!AC$3 -> -1.0008
A55: Morocco | B55: 2022 | C55: Middle East & North Africa | D55: Lower-middle income | E55: =('2019-2022'!E57-'2019-2022'!R$2)/'2019-2022'!R$3 -> -1.1929704 | F55: =('2019-2022'!F57-'2019-2022'!S$2)/'2019-2022'!S$3 -> 1.2411645 | G55: =('2019-2022'!G57-'2019-2022'!T$2)/'2019-2022'!T$3 -> 1.3948453 | H55: =('2019-2022'!H57-'2019-2022'!U$2)/'2019-2022'!U$3 -> -1.1043264 | I55: =('2019-2022'!I57-'2019-2022'!V$2)/'2019-2022'!V$3 -> -1.1255813 | J55: =('2019-2022'!J57-'2019-2022'!W$2)/'2019-2022'!W$3 -> 0.33477899 | K55: =('2019-2022'!K57-'2019-2022'!X$2)/'2019-2022'!X$3 -> 0.57954922 | L55: =('2019-2022'!L57-'2019-2022'!Y$2)/'2019-2022'!Y$3 -> -0.0065605786 | ... P55: =('2019-2022'!P57-'2019-2022'!AC$2)/'2019-2022'!AC$3 -> -1.0090511
A56: Oman | B56: 2019 | C56: Middle East & North Africa | D56: High income | E56: =('2019-2022'!E58-'2019-2022'!R$2)/'2019-2022'!R$3 -> -0.86728232 | F56: =('2019-2022'!F58-'2019-2022'!S$2)/'2019-2022'!S$3 -> 1.3600298 | G56: =('2019-2022'!G58-'2019-2022'!T$2)/'2019-2022'!T$3 -> 1.0213271 | H56: =('2019-2022'!H58-'2019-2022'!U$2)/'2019-2022'!U$3 -> -0.66431208 | I56: =('2019-2022'!I58-'2019-2022'!V$2)/'2019-2022'!V$3 -> -0.95129956 | J56: =('2019-2022'!J58-'2019-2022'!W$2)/'2019-2022'!W$3 -> -0.14355784 | K56: =('2019-2022'!K58-'2019-2022'!X$2)/'2019-2022'!X$3 -> 2.2933761 | L56: =('2019-2022'!L58-'2019-2022'!Y$2)/'2019-2022'!Y$3 -> 1.3066865 | ... P56: =('2019-2022'!P58-'2019-2022'!AC$2)/'2019-2022'!AC$3 -> -0.21737986
A57: Oman | B57: 2020 | C57: Middle East & North Africa | D57: High income | E57: =('2019-2022'!E59-'2019-2022'!R$2)/'2019-2022'!R$3 -> 0.48974665 | F57: =('2019-2022'!F59-'2019-2022'!S$2)/'2019-2022'!S$3 -> 1.5132183 | G57: =('2019-2022'!G59-'2019-2022'!T$2)/'2019-2022'!T$3 -> 0.88884659 | H57: =('2019-2022'!H59-'2019-2022'!U$2)/'2019-2022'!U$3 -> 0.71364537 | I57: =('2019-2022'!I59-'2019-2022'!V$2)/'2019-2022'!V$3 -> 0.33019035 | J57: =('2019-2022'!J59-'2019-2022'!W$2)/'2019-2022'!W$3 -> 0.41210129 | K57: =('2019-2022'!K59-'2019-2022'!X$2)/'2019-2022'!X$3 -> 2.0955619 | L57: =('2019-2022'!L59-'2019-2022'!Y$2)/'2019-2022'!Y$3 -> 2.1911183 | ... P57: =('2019-2022'!P59-'2019-2022'!AC$2)/'2019-2022'!AC$3 -> -0.25694168
... A84: South Africa | B84: 2019 | C84: Sub-Saharan Africa | D84: Upper-middle income | E84: =('2019-2022'!E86-'2019-2022'!R$2)/'2019-2022'!R$3 -> -0.45136251 | F84: =('2019-2022'!F86-'2019-2022'!S$2)/'2019-2022'!S$3 -> 0.11233043 | G84: =('2019-2022'!G86-'2019-2022'!T$2)/'2019-2022'!T$3 -> 0.60143989 | H84: =('2019-2022'!H86-'2019-2022'!U$2)/'2019-2022'!U$3 -> -0.51293479 | I84: =('2019-2022'!I86-'2019-2022'!V$2)/'2019-2022'!V$3 -> -0.38215116 | J84: =('2019-2022'!J86-'2019-2022'!W$2)/'2019-2022'!W$3 -> 0.13183791 | K84: =('2019-2022'!K86-'2019-2022'!X$2)/'2019-2022'!X$3 -> -0.70453444 | L84: =('2019-2022'!L86-'2019-2022'!Y$2)/'2019-2022'!Y$3 -> -1.5755264 | ... P84: =('2019-2022'!P86-'2019-2022'!AC$2)/'2019-2022'!AC$3 -> -0.73712587
A85: South Africa | B85: 2021 | C85: Sub-Saharan Africa | D85: Upper-middle income | E85: =('2019-2022'!E88-'2019-2022'!R$2)/'2019-2022'!R$3 -> 0.6220596 | F85: =('2019-2022'!F88-'2019-2022'!S$2)/'2019-2022'!S$3 -> 1.3331701 | G85: =('2019-2022'!G88-'2019-2022'!T$2)/'2019-2022'!T$3 -> 0.58397246 | H85: =('2019-2022'!H88-'2019-2022'!U$2)/'2019-2022'!U$3 -> 0.87586016 | I85: =('2019-2022'!I88-'2019-2022'!V$2)/'2019-2022'!V$3 -> 0.43702978 | J85: =('2019-2022'!J88-'2019-2022'!W$2)/'2019-2022'!W$3 -> 0.7689127 | K85: =('2019-2022'!K88-'2019-2022'!X$2)/'2019-2022'!X$3 -> 0.16176026 | L85: =('2019-2022'!L88-'2019-2022'!Y$2)/'2019-2022'!Y$3 -> -0.94810685 | ... P85: =('2019-2022'!P88-'2019-2022'!AC$2)/'2019-2022'!AC$3 -> -0.87454355
A86: South Africa | B86: 2022 | C86: Sub-Saharan Africa | D86: Upper-middle income | E86: =('2019-2022'!E89-'2019-2022'!R$2)/'2019-2022'!R$3 -> -0.65357898 | F86: =('2019-2022'!F89-'2019-2022'!S$2)/'2019-2022'!S$3 -> 0.80753252 | G86: =('2019-2022'!G89-'2019-2022'!T$2)/'2019-2022'!T$3 -> 0.55213089 | H86: =('2019-2022'!H89-'2019-2022'!U$2)/'2019-2022'!U$3 -> -0.56670733 | I86: =('2019-2022'!I89-'2019-2022'!V$2)/'2019-2022'!V$3 -> -0.65671853 | J86: =('2019-2022'!J89-'2019-2022'!W$2)/'2019-2022'!W$3 -> 0.36218565 | K86: =('2019-2022'!K89-'2019-2022'!X$2)/'2019-2022'!X$3 -> -1.0681866 | L86: =('2019-2022'!L89-'2019-2022'!Y$2)/'2019-2022'!Y$3 -> -1.2209268 | ... P86: =('2019-2022'!P89-'2019-2022'!AC$2)/'2019-2022'!AC$3 -> -0.98337437
A87: South Korea | B87: 2019 | C87: East Asia & Pacific | D87: High income | E87: =('2019-2022'!E90-'2019-2022'!R$2)/'2019-2022'!R$3 -> -0.61214472 | F87: =('2019-2022'!F90-'2019-2022'!S$2)/'2019-2022'!S$3 -> -1.721471 | G87: =('2019-2022'!G90-'2019-2022'!T$2)/'2019-2022'!T$3 -> -1.9766661 | H87: =('2019-2022'!H90-'2019-2022'!U$2)/'2019-2022'!U$3 -> -1.0312356 | I87: =('2019-2022'!I90-'2019-2022'!V$2)/'2019-2022'!V$3 -> -0.27212782 | J87: =('2019-2022'!J90-'2019-2022'!W$2)/'2019-2022'!W$3 -> -0.45842078 | K87: =('2019-2022'!K90-'2019-2022'!X$2)/'2019-2022'!X$3 -> 0.36595845 | L87: =('2019-2022'!L90-'2019-2022'!Y$2)/'2019-2022'!Y$3 -> -0.98099044 | ... P87: =('2019-2022'!P90-'2019-2022'!AC$2)/'2019-2022'!AC$3 -> 0.34144989
A88: South Korea | B88: 2020 | C88: East Asia & Pacific | D88: High income | E88: =('2019-2022'!E91-'2019-2022'!R$2)/'2019-2022'!R$3 -> -0.53013164 | F88: =('2019-2022'!F91-'2019-2022'!S$2)/'2019-2022'!S$3 -> -1.2612712 | G88: =('2019-2022'!G91-'2019-2022'!T$2)/'2019-2022'!T$3 -> -1.820465 | H88: =('2019-2022'!H91-'2019-2022'!U$2)/'2019-2022'!U$3 -> -0.67308574 | I88: =('2019-2022'!I91-'2019-2022'!V$2)/'2019-2022'!V$3 -> -0.39647565 | J88: =('2019-2022'!J91-'2019-2022'!W$2)/'2019-2022'!W$3 -> -0.36901931 | K88: =('2019-2022'!K91-'2019-2022'!X$2)/'2019-2022'!X$3 -> 0.45165737 | L88: =('2019-2022'!L91-'2019-2022'!Y$2)/'2019-2022'!Y$3 -> -0.79140094 | ... P88: =('2019-2022'!P91-'2019-2022'!AC$2)/'2019-2022'!AC$3 -> 0.33642479
